<mujoco model="go2_description">
  <option iterations="50" timestep="0.001" solver="PGS" gravity="0 0 -9.81" />

  <compiler angle="radian" meshdir="meshes" eulerseq="zyx" autolimits="true" />

  <default>
    <joint limited="true" damping="0.01" armature="0.01" frictionloss="0.01" />
    <geom condim="4" contype="1" conaffinity="15" friction="0.9 0.2 0.2" solref="0.001 2" />
    <motor ctrllimited="true" />
    <equality solref="0.001 2" />
    <default class="visualgeom">
      <geom material="visualgeom" condim="1" contype="0" conaffinity="0" />
    </default>
  </default>

  <worldbody>
    <light directional="true" diffuse="0.4 0.4 0.4" specular="0.1 0.1 0.1" pos="0 0 5.0" dir="0 0 -1" castshadow="false" />
    <light directional="true" diffuse="0.6 0.6 0.6" specular="0.2 0.2 0.2" pos="0 0 4" dir="0 0 -1" />
    <geom name="ground" type="plane" pos="0 0 0" size="100 100 0.001" quat="1 0 0 0" material="matplane" condim="3" conaffinity="15" />
    <camera name="fixed" pos="0 -3.0 0.9259999999999999" xyaxes="1 0 0 0 0 1" />
    <camera name="track" mode="trackcom" pos="0 -3.0 0.9259999999999999" xyaxes="1 0 0 0 0 1" />
    <body name="root" pos="0 0 0.426" quat="1 0 0 0">
      <freejoint name="root" />
      <site name="imu" size="0.01" pos="0 0 0" />
      <geom size="0.1881 0.04675 0.057" type="box" rgba="1 1 1 1" contype="1" conaffinity="0" density="0" group="1" class="visualgeom" />
      <geom type="box" rgba="1 1 1 1" size="0.1881 0.04675 0.057" />
      <geom size="0.05 0.045" pos="0.285 0 0.01" type="cylinder" contype="1" conaffinity="0" density="0" group="1" class="visualgeom" />
      <geom type="cylinder" rgba="" pos="0.285 0 0.01" />
      <geom size="0.047" pos="0.293 0 -0.06" contype="1" conaffinity="0" density="0" group="1" class="visualgeom" />
      <geom type="" rgba="" pos="0.293 0 -0.06" />
      <body name="FL_hip" pos="0.1934 0.0465 0" gravcomp="0">
        <inertial pos="-0.0054 0.00194 -0.000105" quat="0.497014 0.499245 0.505462 0.498237" mass="0.678" diaginertia="0.00088403 0.000596003 0.000479967" />
        <joint name="FL_hip_joint" pos="0 0 0" axis="1 0 0" range="-1.0472 1.0472" />
        <geom size="0.046 0.02" pos="0 0.08 0" quat="0.707107 0.707107 0 0" type="cylinder" rgba="1 1 1 1" contype="1" conaffinity="0" density="0" group="1" class="visualgeom" />
        <geom type="cylinder" rgba="1 1 1 1" pos="0 0.08 0" quat="0.707107 0.707107 0 0" />
        <body name="FL_thigh" pos="0 0.0955 0" gravcomp="0">
          <inertial pos="-0.00374 -0.0223 -0.0327" quat="0.829533 0.0847635 -0.0200632 0.551623" mass="1.152" diaginertia="0.00594973 0.00584149 0.000878787" />
          <joint name="FL_thigh_joint" pos="0 0 0" axis="0 1 0" range="-1.5708 3.4907" />
          <geom size="0.055 0.01225 0.017" pos="0 0 -0.1065" quat="0.707107 0 0.707107 0" type="box" rgba="1 1 1 1" contype="1" conaffinity="0" density="0" group="1" class="visualgeom" />
          <geom type="box" rgba="1 1 1 1" size="0.055 0.01225 0.017" pos="0 0 -0.1065" quat="0.707107 0 0.707107 0" />
          <body name="FL_calf" pos="0 0 -0.213" gravcomp="0">
            <inertial pos="0.00629595 -0.000622121 -0.141417" quat="0.710672 0.00154099 -0.00450087 0.703508" mass="0.241352" diaginertia="0.0014901 0.00146356 5.31397e-05" />
            <joint name="FL_calf_joint" pos="0 0 0" axis="0 1 0" range="-2.7227 -0.83776" />
            <geom size="0.012 0.06" pos="0.008 0 -0.06" quat="0.994493 0 -0.104807 0" type="cylinder" rgba="1 1 1 1" contype="1" conaffinity="0" density="0" group="1" class="visualgeom" />
            <geom type="cylinder" rgba="1 1 1 1" pos="0.008 0 -0.06" quat="0.994493 0 -0.104807 0" />
            <geom size="0.011 0.0325" pos="0.02 0 -0.148" quat="0.999688 0 0.0249974 0" type="cylinder" contype="1" conaffinity="0" density="0" group="1" class="visualgeom" />
            <geom type="cylinder" rgba="" pos="0.02 0 -0.148" quat="0.999688 0 0.0249974 0" />
            <geom size="0.0155 0.015" pos="0.00801333 0 -0.18745" quat="0.965093 0 0.261909 0" type="cylinder" contype="1" conaffinity="0" density="0" group="1" class="visualgeom" />
            <geom type="cylinder" rgba="" pos="0.00801333 0 -0.18745" quat="0.965093 0 0.261909 0" />
            <geom size="0.022" pos="-0.002 0 -0.213" rgba="1 1 1 1" contype="1" conaffinity="0" density="0" group="1" class="visualgeom" />
            <geom type="" rgba="1 1 1 1" pos="-0.002 0 -0.213" />
          </body>
        </body>
      </body>
      <body name="FR_hip" pos="0.1934 -0.0465 0" gravcomp="0">
        <inertial pos="-0.0054 -0.00194 -0.000105" quat="0.498237 0.505462 0.499245 0.497014" mass="0.678" diaginertia="0.00088403 0.000596003 0.000479967" />
        <joint name="FR_hip_joint" pos="0 0 0" axis="1 0 0" range="-1.0472 1.0472" />
        <geom size="0.046 0.02" pos="0 -0.08 0" quat="0.707107 0.707107 0 0" type="cylinder" rgba="1 1 1 1" contype="1" conaffinity="0" density="0" group="1" class="visualgeom" />
        <geom type="cylinder" rgba="1 1 1 1" pos="0 -0.08 0" quat="0.707107 0.707107 0 0" />
        <body name="FR_thigh" pos="0 -0.0955 0" gravcomp="0">
          <inertial pos="-0.00374 0.0223 -0.0327" quat="0.551623 -0.0200632 0.0847635 0.829533" mass="1.152" diaginertia="0.00594973 0.00584149 0.000878787" />
          <joint name="FR_thigh_joint" pos="0 0 0" axis="0 1 0" range="-1.5708 3.4907" />
          <geom size="0.055 0.01225 0.017" pos="0 0 -0.1065" quat="0.707107 0 0.707107 0" type="box" rgba="1 1 1 1" contype="1" conaffinity="0" density="0" group="1" class="visualgeom" />
          <geom type="box" rgba="1 1 1 1" size="0.055 0.01225 0.017" pos="0 0 -0.1065" quat="0.707107 0 0.707107 0" />
          <body name="FR_calf" pos="0 0 -0.213" gravcomp="0">
            <inertial pos="0.00629595 0.000622121 -0.141417" quat="0.703508 -0.00450087 0.00154099 0.710672" mass="0.241352" diaginertia="0.0014901 0.00146356 5.31397e-05" />
            <joint name="FR_calf_joint" pos="0 0 0" axis="0 1 0" range="-2.7227 -0.83776" />
            <geom size="0.013 0.06" pos="0.01 0 -0.06" quat="0.995004 0 -0.0998334 0" type="cylinder" rgba="1 1 1 1" contype="1" conaffinity="0" density="0" group="1" class="visualgeom" />
            <geom type="cylinder" rgba="1 1 1 1" pos="0.01 0 -0.06" quat="0.995004 0 -0.0998334 0" />
            <geom size="0.011 0.0325" pos="0.02 0 -0.148" quat="0.999688 0 0.0249974 0" type="cylinder" contype="1" conaffinity="0" density="0" group="1" class="visualgeom" />
            <geom type="cylinder" rgba="" pos="0.02 0 -0.148" quat="0.999688 0 0.0249974 0" />
            <geom size="0.0155 0.015" pos="0.00801333 0 -0.18745" quat="0.965093 0 0.261909 0" type="cylinder" contype="1" conaffinity="0" density="0" group="1" class="visualgeom" />
            <geom type="cylinder" rgba="" pos="0.00801333 0 -0.18745" quat="0.965093 0 0.261909 0" />
            <geom size="0.022" pos="-0.002 0 -0.213" rgba="1 1 1 1" contype="1" conaffinity="0" density="0" group="1" class="visualgeom" />
            <geom type="" rgba="1 1 1 1" pos="-0.002 0 -0.213" />
          </body>
        </body>
      </body>
      <body name="RL_hip" pos="-0.1934 0.0465 0" gravcomp="0">
        <inertial pos="0.0054 0.00194 -0.000105" quat="0.505462 0.498237 0.497014 0.499245" mass="0.678" diaginertia="0.00088403 0.000596003 0.000479967" />
        <joint name="RL_hip_joint" pos="0 0 0" axis="1 0 0" range="-1.0472 1.0472" />
        <geom size="0.046 0.02" pos="0 0.08 0" quat="0.707107 0.707107 0 0" type="cylinder" rgba="1 1 1 1" contype="1" conaffinity="0" density="0" group="1" class="visualgeom" />
        <geom type="cylinder" rgba="1 1 1 1" pos="0 0.08 0" quat="0.707107 0.707107 0 0" />
        <body name="RL_thigh" pos="0 0.0955 0" gravcomp="0">
          <inertial pos="-0.00374 -0.0223 -0.0327" quat="0.829533 0.0847635 -0.0200632 0.551623" mass="1.152" diaginertia="0.00594973 0.00584149 0.000878787" />
          <joint name="RL_thigh_joint" pos="0 0 0" axis="0 1 0" range="-0.5236 4.5379" />
          <geom size="0.055 0.01225 0.017" pos="0 0 -0.1065" quat="0.707107 0 0.707107 0" type="box" rgba="1 1 1 1" contype="1" conaffinity="0" density="0" group="1" class="visualgeom" />
          <geom type="box" rgba="1 1 1 1" size="0.055 0.01225 0.017" pos="0 0 -0.1065" quat="0.707107 0 0.707107 0" />
          <body name="RL_calf" pos="0 0 -0.213" gravcomp="0">
            <inertial pos="0.00629595 -0.000622121 -0.141417" quat="0.710672 0.00154099 -0.00450087 0.703508" mass="0.241352" diaginertia="0.0014901 0.00146356 5.31397e-05" />
            <joint name="RL_calf_joint" pos="0 0 0" axis="0 1 0" range="-2.7227 -0.83776" />
            <geom size="0.013 0.06" pos="0.01 0 -0.06" quat="0.995004 0 -0.0998334 0" type="cylinder" rgba="1 1 1 1" contype="1" conaffinity="0" density="0" group="1" class="visualgeom" />
            <geom type="cylinder" rgba="1 1 1 1" pos="0.01 0 -0.06" quat="0.995004 0 -0.0998334 0" />
            <geom size="0.011 0.0325" pos="0.02 0 -0.148" quat="0.999688 0 0.0249974 0" type="cylinder" contype="1" conaffinity="0" density="0" group="1" class="visualgeom" />
            <geom type="cylinder" rgba="" pos="0.02 0 -0.148" quat="0.999688 0 0.0249974 0" />
            <geom size="0.0155 0.015" pos="0.00801333 0 -0.18745" quat="0.965093 0 0.261909 0" type="cylinder" contype="1" conaffinity="0" density="0" group="1" class="visualgeom" />
            <geom type="cylinder" rgba="" pos="0.00801333 0 -0.18745" quat="0.965093 0 0.261909 0" />
            <geom size="0.022" pos="-0.002 0 -0.213" rgba="1 1 1 1" contype="1" conaffinity="0" density="0" group="1" class="visualgeom" />
            <geom type="" rgba="1 1 1 1" pos="-0.002 0 -0.213" />
          </body>
        </body>
      </body>
      <body name="RR_hip" pos="-0.1934 -0.0465 0" gravcomp="0">
        <inertial pos="0.0054 -0.00194 -0.000105" quat="0.499245 0.497014 0.498237 0.505462" mass="0.678" diaginertia="0.00088403 0.000596003 0.000479967" />
        <joint name="RR_hip_joint" pos="0 0 0" axis="1 0 0" range="-1.0472 1.0472" />
        <geom size="0.046 0.02" pos="0 -0.08 0" quat="0.707107 0.707107 0 0" type="cylinder" rgba="1 1 1 1" contype="1" conaffinity="0" density="0" group="1" class="visualgeom" />
        <geom type="cylinder" rgba="1 1 1 1" pos="0 -0.08 0" quat="0.707107 0.707107 0 0" />
        <body name="RR_thigh" pos="0 -0.0955 0" gravcomp="0">
          <inertial pos="-0.00374 0.0223 -0.0327" quat="0.551623 -0.0200632 0.0847635 0.829533" mass="1.152" diaginertia="0.00594973 0.00584149 0.000878787" />
          <joint name="RR_thigh_joint" pos="0 0 0" axis="0 1 0" range="-0.5236 4.5379" />
          <geom size="0.055 0.01225 0.017" pos="0 0 -0.1065" quat="0.707107 0 0.707107 0" type="box" rgba="1 1 1 1" contype="1" conaffinity="0" density="0" group="1" class="visualgeom" />
          <geom type="box" rgba="1 1 1 1" size="0.055 0.01225 0.017" pos="0 0 -0.1065" quat="0.707107 0 0.707107 0" />
          <body name="RR_calf" pos="0 0 -0.213" gravcomp="0">
            <inertial pos="0.00629595 0.000622121 -0.141417" quat="0.703508 -0.00450087 0.00154099 0.710672" mass="0.241352" diaginertia="0.0014901 0.00146356 5.31397e-05" />
            <joint name="RR_calf_joint" pos="0 0 0" axis="0 1 0" range="-2.7227 -0.83776" />
            <geom size="0.013 0.06" pos="0.01 0 -0.06" quat="0.995004 0 -0.0998334 0" type="cylinder" rgba="1 1 1 1" contype="1" conaffinity="0" density="0" group="1" class="visualgeom" />
            <geom type="cylinder" rgba="1 1 1 1" pos="0.01 0 -0.06" quat="0.995004 0 -0.0998334 0" />
            <geom size="0.011 0.0325" pos="0.02 0 -0.148" quat="0.999688 0 0.0249974 0" type="cylinder" contype="1" conaffinity="0" density="0" group="1" class="visualgeom" />
            <geom type="cylinder" rgba="" pos="0.02 0 -0.148" quat="0.999688 0 0.0249974 0" />
            <geom size="0.0155 0.015" pos="0.00801333 0 -0.18745" quat="0.965093 0 0.261909 0" type="cylinder" contype="1" conaffinity="0" density="0" group="1" class="visualgeom" />
            <geom type="cylinder" rgba="" pos="0.00801333 0 -0.18745" quat="0.965093 0 0.261909 0" />
            <geom size="0.022" pos="-0.002 0 -0.213" rgba="1 1 1 1" contype="1" conaffinity="0" density="0" group="1" class="visualgeom" />
            <geom type="" rgba="1 1 1 1" pos="-0.002 0 -0.213" />
          </body>
        </body>
      </body>
    </body>
  </worldbody>

  <asset>
    <texture name="texplane" type="2d" builtin="checker" rgb1=".0 .0 .0" rgb2=".8 .8 .8" width="100" height="100" />
    <material name="matplane" reflectance="0." texture="texplane" texrepeat="1 1" texuniform="true" />
    <material name="visualgeom" rgba="0.5 0.9 0.2 1" />
  </asset>

  <actuator>
    <motor name="FL_hip_joint" joint="FL_hip_joint" ctrllimited="true" ctrlrange="-1 1" gear="1" />
    <motor name="FL_thigh_joint" joint="FL_thigh_joint" ctrllimited="true" ctrlrange="-1 1" gear="1" />
    <motor name="FL_calf_joint" joint="FL_calf_joint" ctrllimited="true" ctrlrange="-1 1" gear="1" />
    <motor name="FR_hip_joint" joint="FR_hip_joint" ctrllimited="true" ctrlrange="-1 1" gear="1" />
    <motor name="FR_thigh_joint" joint="FR_thigh_joint" ctrllimited="true" ctrlrange="-1 1" gear="1" />
    <motor name="FR_calf_joint" joint="FR_calf_joint" ctrllimited="true" ctrlrange="-1 1" gear="1" />
    <motor name="RL_hip_joint" joint="RL_hip_joint" ctrllimited="true" ctrlrange="-1 1" gear="1" />
    <motor name="RL_thigh_joint" joint="RL_thigh_joint" ctrllimited="true" ctrlrange="-1 1" gear="1" />
    <motor name="RL_calf_joint" joint="RL_calf_joint" ctrllimited="true" ctrlrange="-1 1" gear="1" />
    <motor name="RR_hip_joint" joint="RR_hip_joint" ctrllimited="true" ctrlrange="-1 1" gear="1" />
    <motor name="RR_thigh_joint" joint="RR_thigh_joint" ctrllimited="true" ctrlrange="-1 1" gear="1" />
    <motor name="RR_calf_joint" joint="RR_calf_joint" ctrllimited="true" ctrlrange="-1 1" gear="1" />
  </actuator>

  <sensor>
    <actuatorpos name="FL_hip_joint_p" actuator="FL_hip_joint" />
    <actuatorvel name="FL_hip_joint_v" actuator="FL_hip_joint" />
    <actuatorfrc name="FL_hip_joint_f" actuator="FL_hip_joint" noise="0.001" />
    <actuatorpos name="FL_thigh_joint_p" actuator="FL_thigh_joint" />
    <actuatorvel name="FL_thigh_joint_v" actuator="FL_thigh_joint" />
    <actuatorfrc name="FL_thigh_joint_f" actuator="FL_thigh_joint" noise="0.001" />
    <actuatorpos name="FL_calf_joint_p" actuator="FL_calf_joint" />
    <actuatorvel name="FL_calf_joint_v" actuator="FL_calf_joint" />
    <actuatorfrc name="FL_calf_joint_f" actuator="FL_calf_joint" noise="0.001" />
    <actuatorpos name="FR_hip_joint_p" actuator="FR_hip_joint" />
    <actuatorvel name="FR_hip_joint_v" actuator="FR_hip_joint" />
    <actuatorfrc name="FR_hip_joint_f" actuator="FR_hip_joint" noise="0.001" />
    <actuatorpos name="FR_thigh_joint_p" actuator="FR_thigh_joint" />
    <actuatorvel name="FR_thigh_joint_v" actuator="FR_thigh_joint" />
    <actuatorfrc name="FR_thigh_joint_f" actuator="FR_thigh_joint" noise="0.001" />
    <actuatorpos name="FR_calf_joint_p" actuator="FR_calf_joint" />
    <actuatorvel name="FR_calf_joint_v" actuator="FR_calf_joint" />
    <actuatorfrc name="FR_calf_joint_f" actuator="FR_calf_joint" noise="0.001" />
    <actuatorpos name="RL_hip_joint_p" actuator="RL_hip_joint" />
    <actuatorvel name="RL_hip_joint_v" actuator="RL_hip_joint" />
    <actuatorfrc name="RL_hip_joint_f" actuator="RL_hip_joint" noise="0.001" />
    <actuatorpos name="RL_thigh_joint_p" actuator="RL_thigh_joint" />
    <actuatorvel name="RL_thigh_joint_v" actuator="RL_thigh_joint" />
    <actuatorfrc name="RL_thigh_joint_f" actuator="RL_thigh_joint" noise="0.001" />
    <actuatorpos name="RL_calf_joint_p" actuator="RL_calf_joint" />
    <actuatorvel name="RL_calf_joint_v" actuator="RL_calf_joint" />
    <actuatorfrc name="RL_calf_joint_f" actuator="RL_calf_joint" noise="0.001" />
    <actuatorpos name="RR_hip_joint_p" actuator="RR_hip_joint" />
    <actuatorvel name="RR_hip_joint_v" actuator="RR_hip_joint" />
    <actuatorfrc name="RR_hip_joint_f" actuator="RR_hip_joint" noise="0.001" />
    <actuatorpos name="RR_thigh_joint_p" actuator="RR_thigh_joint" />
    <actuatorvel name="RR_thigh_joint_v" actuator="RR_thigh_joint" />
    <actuatorfrc name="RR_thigh_joint_f" actuator="RR_thigh_joint" noise="0.001" />
    <actuatorpos name="RR_calf_joint_p" actuator="RR_calf_joint" />
    <actuatorvel name="RR_calf_joint_v" actuator="RR_calf_joint" />
    <actuatorfrc name="RR_calf_joint_f" actuator="RR_calf_joint" noise="0.001" />
    <framequat name="orientation" objtype="site" noise="0.001" objname="imu" />
    <gyro name="angular-velocity" site="imu" noise="0.005" cutoff="34.9" />
  </sensor>
</mujoco>